# Debugging Log: Task 9.2 - Batch 8 gRPC API Failures

**Date:** 2025-04-10
**Context:** Fixing runtime test failures for Task 9.2 (from `TASK.md`). Focusing on Batch 8: `ops_core/tests/grpc/`.
**Goal:** Identify and resolve the 4 failures reported in `test_task_servicer.py`.

## Initial Symptom (from batch tox run)

*Command Used:* `tox -e py312 -- ops_core/tests/grpc/test_task_servicer.py -v`

```
FAILED ops_core/tests/grpc/test_task_servicer.py::test_get_task_not_found - AssertionError: expected await not found. ... (INTERNAL vs NOT_FOUND status code) ... got Future <Future pending cb=[BaseProtocol._on_waiter_completed()]> attached to a different loop")
FAILED ops_core/tests/grpc/test_task_servicer.py::test_get_task_metadata_store_error - AssertionError: expected await not found. ... (InterfaceError vs Simulated DB connection lost) ... cannot perform operation: another operation is in progress
FAILED ops_core/tests/grpc/test_task_servicer.py::test_list_tasks_success - assert 0 == 2 ... (InterfaceError likely preventing data retrieval)
FAILED ops_core/tests/grpc/test_task_servicer.py::test_list_tasks_metadata_store_error - AssertionError: expected await not found. ... (InterfaceError vs Simulated query failed) ... cannot perform operation: another operation is in progress
```
*(Underlying cause appears to be `sqlalchemy.exc.InterfaceError: cannot perform operation: another operation is in progress` and potentially asyncio loop issues)*

## Affected Batch/Area

`ops_core/tests/grpc/test_task_servicer.py`

## Isolation Command(s)

`tox -e py312 -- ops_core/tests/grpc/test_task_servicer.py::test_get_task_not_found -v` (Example for first test)

## Debugging Log (Chronological)

- **2025-04-10 6:21 PM:** Identified 4 failing tests via batch run: `test_get_task_not_found`, `test_get_task_metadata_store_error`, `test_list_tasks_success`, `test_list_tasks_metadata_store_error`. Common error involves `InterfaceError: cannot perform operation: another operation is in progress`.
- **2025-04-10 6:22 PM:** Starting debug with `test_get_task_not_found`. Isolated test run confirmed failure (`AssertionError: expected await not found. ... (INTERNAL vs NOT_FOUND status code)`).
- **2025-04-10 6:23 PM:** **Fix 1:** Modified `src/ops_core/grpc_internal/task_servicer.py::GetTask` to specifically catch `TaskNotFoundError` and abort with `StatusCode.NOT_FOUND`. Re-ran test `test_get_task_not_found`. **Result: PASSED.**
- **2025-04-10 6:23 PM:** Addressing next failure: `test_get_task_metadata_store_error`. Isolated test run confirmed failure (`AssertionError: expected await not found. ... (InterfaceError vs Simulated DB connection lost)`). Issue was patching `db_session.execute` instead of the store method used by the servicer.
- **2025-04-10 6:24 PM:** **Fix 2:** Modified `ops_core/tests/grpc/test_task_servicer.py::test_get_task_metadata_store_error` to patch `task_servicer._metadata_store.get_task` directly. Re-ran test `test_get_task_metadata_store_error`. **Result: PASSED.**
- **2025-04-10 6:24 PM:** Addressing next failure: `test_list_tasks_success`. Isolated test run confirmed failure (`AssertionError: assert 0 == 2`). Likely due to session conflict preventing data visibility.
- **2025-04-10 6:25 PM:** **Fix 3:** Modified `ops_core/tests/grpc/test_task_servicer.py::task_servicer` fixture to pass the `db_session` fixture to the `SqlMetadataStore` constructor (`SqlMetadataStore(session=db_session)`). Re-ran test `test_list_tasks_success`. **Result: PASSED.**
- **2025-04-10 6:25 PM:** Addressing final failure: `test_list_tasks_metadata_store_error`. Isolated test run confirmed failure (`AssertionError: expected await not found. ... (InterfaceError vs Simulated query failed)`). Issue was patching `db_session.execute` instead of the store method.
- **2025-04-10 6:25 PM:** **Fix 4:** Modified `ops_core/tests/grpc/test_task_servicer.py::test_list_tasks_metadata_store_error` to patch `task_servicer._metadata_store.list_tasks` directly. Re-ran test `test_list_tasks_metadata_store_error`. **Result: PASSED.**
- **2025-04-10 6:26 PM:** Ran full batch test command `tox -e py312 -- ops_core/tests/grpc/test_task_servicer.py -v`. **Result: All 9 tests PASSED.**

## Root Cause

1.  **Incorrect Exception Handling:** `TaskServicer.GetTask` used a generic `except Exception` block, masking the specific `TaskNotFoundError` and returning `StatusCode.INTERNAL` instead of `StatusCode.NOT_FOUND`.
2.  **Session Mismatch:** The `task_servicer` fixture created an `SqlMetadataStore` instance without passing the test's `db_session`. This meant the store used its own internal session, separate from the one used by the test to set up data, leading to `InterfaceError` or tests not finding data (`test_list_tasks_success`).
3.  **Incorrect Patching:** Tests simulating store errors were patching the `db_session.execute` method instead of the relevant method (`get_task`, `list_tasks`) on the actual `SqlMetadataStore` instance used by the servicer fixture.

## Solution/Fix

1.  Added specific `except TaskNotFoundError` block in `TaskServicer.GetTask`.
2.  Modified the `task_servicer` fixture in `test_task_servicer.py` to inject the `db_session` into the `SqlMetadataStore` constructor.
3.  Modified `test_get_task_metadata_store_error` and `test_list_tasks_metadata_store_error` to patch the appropriate methods (`get_task`, `list_tasks`) directly on the `task_servicer._metadata_store` object using `mocker.patch.object`.

## Verification Steps

`tox -e py312 -- ops_core/tests/grpc/test_task_servicer.py -v` resulted in 9 passes.

## Learnings/Takeaways

- Ensure specific exceptions are handled appropriately before generic ones.
- When testing components that interact with database sessions managed by fixtures, ensure the component instance under test receives the *same* session object used by the test setup (often via fixture modification or dependency injection overrides).
- When mocking methods on dependencies, ensure the patch targets the actual instance being used by the code under test, not just a generic class or a different instance (like the session fixture itself).
